{"name": "test_update_users[NoValid- Book not found]", "status": "failed", "statusDetails": {"message": "Failed: [ERROR] Invalid id from Excel: '0.0'", "trace": "self = <tests.test_api_resource.TestusersAPI object at 0x00000227A99496A0>, data = {'action': 'update_by_id', 'expected': True, 'job': '', 'name': 'Nobody', ...}\n\n    @allure.description(\"Updates users details by users ID.\")\n    @pytest.mark.parametrize(*load_test_data(\"apis\", \"update_by_id\", parametrize=True))\n    def test_update_users(self, data):\n        expected = parse_bool(data.get(\"expected\"))\n        try:\n>           id = extract_id(data, fallback_id=self.__class__.created_ids[0])\nE           IndexError: list index out of range\n\ntests\\test_api_resource.py:45: IndexError\n\nDuring handling of the above exception, another exception occurred:\n\nself = <tests.test_api_resource.TestusersAPI object at 0x00000227A99496A0>, data = {'action': 'update_by_id', 'expected': True, 'job': '', 'name': 'Nobody', ...}\n\n    @allure.description(\"Updates users details by users ID.\")\n    @pytest.mark.parametrize(*load_test_data(\"apis\", \"update_by_id\", parametrize=True))\n    def test_update_users(self, data):\n        expected = parse_bool(data.get(\"expected\"))\n        try:\n            id = extract_id(data, fallback_id=self.__class__.created_ids[0])\n        except Exception:\n>           pytest.fail(f\"[ERROR] Invalid id from Excel: '{data.get('id')}'\")\nE           Failed: [ERROR] Invalid id from Excel: '0.0'\n\ntests\\test_api_resource.py:47: Failed"}, "description": "Updates users details by users ID.", "attachments": [{"name": "‚è∞ Test Start Time", "source": "a43c542c-ca5a-4efb-a584-95b1964ec87e-attachment.txt", "type": "text/plain"}, {"name": "üèÅ Test End Time", "source": "5c627b4b-62ff-445f-9fc4-248804f89fed-attachment.txt", "type": "text/plain"}, {"name": "‚è±Ô∏è Test Duration", "source": "4cc99c85-a158-41d7-9cbc-eaeb6c165bf8-attachment.txt", "type": "text/plain"}, {"name": "[None] request", "source": "67185956-710b-4580-9388-fc09bec82b3a-attachment.txt", "type": "text/plain"}, {"name": "Allure Attachment Error", "source": "6f39cfe3-5ac9-49d1-9ca4-9f7967b62d62-attachment.txt", "type": "text/plain"}], "parameters": [{"name": "data", "value": "{'action': 'update_by_id', 'id': 0.0, 'name': 'Nobody', 'job': '', 'expected': True, 'note': 'NoValid- Book not found'}"}], "start": 1753288083927, "stop": 1753288083929, "uuid": "41dc380a-0b3a-48f4-baa4-08db404653f7", "historyId": "0c69d8e795745ed4145a7a5bb1271633", "testCaseId": "606f5d6c173cdf14acb8881bab7fb526", "fullName": "tests.test_api_resource.TestusersAPI#test_update_users", "labels": [{"name": "epic", "value": "users API"}, {"name": "tag", "value": "@pytest.mark.usefixtures('setup')"}, {"name": "tag", "value": "api"}, {"name": "parentSuite", "value": "tests"}, {"name": "suite", "value": "test_api_resource"}, {"name": "subSuite", "value": "TestusersAPI"}, {"name": "host", "value": "Saber"}, {"name": "thread", "value": "17972-MainThread"}, {"name": "framework", "value": "pytest"}, {"name": "language", "value": "cpython3"}, {"name": "package", "value": "tests.test_api_resource"}]}