{"name": "test_update_users[NoValid- Book not found]", "status": "failed", "statusDetails": {"message": "Failed: [ERROR] Invalid id from Excel: '0.0'", "trace": "self = <tests.test_api_resource.TestusersAPI object at 0x00000211267416A0>, data = {'action': 'update_by_id', 'expected': True, 'job': '', 'name': 'Nobody', ...}\n\n    @allure.description(\"Updates users details by users ID.\")\n    @pytest.mark.parametrize(*load_test_data(\"apis\", \"update_by_id\", parametrize=True))\n    def test_update_users(self, data):\n        expected = parse_bool(data.get(\"expected\"))\n        try:\n>           id = extract_id(data, fallback_id=self.__class__.created_ids[0])\nE           IndexError: list index out of range\n\ntests\\test_api_resource.py:45: IndexError\n\nDuring handling of the above exception, another exception occurred:\n\nself = <tests.test_api_resource.TestusersAPI object at 0x00000211267416A0>, data = {'action': 'update_by_id', 'expected': True, 'job': '', 'name': 'Nobody', ...}\n\n    @allure.description(\"Updates users details by users ID.\")\n    @pytest.mark.parametrize(*load_test_data(\"apis\", \"update_by_id\", parametrize=True))\n    def test_update_users(self, data):\n        expected = parse_bool(data.get(\"expected\"))\n        try:\n            id = extract_id(data, fallback_id=self.__class__.created_ids[0])\n        except Exception:\n>           pytest.fail(f\"[ERROR] Invalid id from Excel: '{data.get('id')}'\")\nE           Failed: [ERROR] Invalid id from Excel: '0.0'\n\ntests\\test_api_resource.py:47: Failed"}, "description": "Updates users details by users ID.", "attachments": [{"name": "‚è∞ Test Start Time", "source": "7f0f04c4-0962-4aa0-a781-d4e363d09151-attachment.txt", "type": "text/plain"}, {"name": "üèÅ Test End Time", "source": "52f1699c-5927-4479-bf44-e527159e4fe4-attachment.txt", "type": "text/plain"}, {"name": "‚è±Ô∏è Test Duration", "source": "9494c2ef-7311-4a30-b549-621b9b30723d-attachment.txt", "type": "text/plain"}, {"name": "[None] request", "source": "864ddf42-90e4-4a4a-ab11-2e0b9393eb6f-attachment.txt", "type": "text/plain"}, {"name": "Allure Attachment Error", "source": "b88440b2-8d8b-45d4-a352-64fb85d4785f-attachment.txt", "type": "text/plain"}], "parameters": [{"name": "data", "value": "{'action': 'update_by_id', 'id': 0.0, 'name': 'Nobody', 'job': '', 'expected': True, 'note': 'NoValid- Book not found'}"}], "start": 1753287877705, "stop": 1753287877707, "uuid": "9a35b4ba-fd5e-49ee-85de-fe032b152598", "historyId": "0c69d8e795745ed4145a7a5bb1271633", "testCaseId": "606f5d6c173cdf14acb8881bab7fb526", "fullName": "tests.test_api_resource.TestusersAPI#test_update_users", "labels": [{"name": "epic", "value": "users API"}, {"name": "tag", "value": "@pytest.mark.usefixtures('setup')"}, {"name": "tag", "value": "api"}, {"name": "parentSuite", "value": "tests"}, {"name": "suite", "value": "test_api_resource"}, {"name": "subSuite", "value": "TestusersAPI"}, {"name": "host", "value": "Saber"}, {"name": "thread", "value": "16924-MainThread"}, {"name": "framework", "value": "pytest"}, {"name": "language", "value": "cpython3"}, {"name": "package", "value": "tests.test_api_resource"}]}