{"name": "test_update_users[NoValid- Book not found]", "status": "failed", "statusDetails": {"message": "Failed: [ERROR] Invalid id from Excel: '0.0'", "trace": "self = <tests.test_api_resource.TestusersAPI object at 0x0000022C0C79D6A0>, data = {'action': 'update_by_id', 'expected': True, 'job': '', 'name': 'Nobody', ...}\n\n    @allure.description(\"Updates users details by users ID.\")\n    @pytest.mark.parametrize(*load_test_data(\"apis\", \"update_by_id\", parametrize=True))\n    def test_update_users(self, data):\n        expected = parse_bool(data.get(\"expected\"))\n        try:\n>           id = extract_id(data, fallback_id=self.__class__.created_ids[0])\nE           IndexError: list index out of range\n\ntests\\test_api_resource.py:45: IndexError\n\nDuring handling of the above exception, another exception occurred:\n\nself = <tests.test_api_resource.TestusersAPI object at 0x0000022C0C79D6A0>, data = {'action': 'update_by_id', 'expected': True, 'job': '', 'name': 'Nobody', ...}\n\n    @allure.description(\"Updates users details by users ID.\")\n    @pytest.mark.parametrize(*load_test_data(\"apis\", \"update_by_id\", parametrize=True))\n    def test_update_users(self, data):\n        expected = parse_bool(data.get(\"expected\"))\n        try:\n            id = extract_id(data, fallback_id=self.__class__.created_ids[0])\n        except Exception:\n>           pytest.fail(f\"[ERROR] Invalid id from Excel: '{data.get('id')}'\")\nE           Failed: [ERROR] Invalid id from Excel: '0.0'\n\ntests\\test_api_resource.py:47: Failed"}, "description": "Updates users details by users ID.", "attachments": [{"name": "‚è∞ Test Start Time", "source": "e4e588a9-af49-4b94-92d5-b74b69f1a15a-attachment.txt", "type": "text/plain"}, {"name": "üèÅ Test End Time", "source": "84157605-93d3-4761-a6c8-32f6dd37ddb1-attachment.txt", "type": "text/plain"}, {"name": "‚è±Ô∏è Test Duration", "source": "28106f5d-c60a-48f7-bc32-a08aa74a3fed-attachment.txt", "type": "text/plain"}, {"name": "[None] request", "source": "5d09f611-aba0-41b3-b2ea-7df017a66324-attachment.txt", "type": "text/plain"}, {"name": "Allure Attachment Error", "source": "50e14d3c-6fe8-4b66-b8d5-8f8cc01cc724-attachment.txt", "type": "text/plain"}], "parameters": [{"name": "data", "value": "{'action': 'update_by_id', 'id': 0.0, 'name': 'Nobody', 'job': '', 'expected': True, 'note': 'NoValid- Book not found'}"}], "start": 1753285836561, "stop": 1753285836562, "uuid": "0afaecd9-321a-4b61-ad33-e10cc3af30ab", "historyId": "0c69d8e795745ed4145a7a5bb1271633", "testCaseId": "606f5d6c173cdf14acb8881bab7fb526", "fullName": "tests.test_api_resource.TestusersAPI#test_update_users", "labels": [{"name": "epic", "value": "users API"}, {"name": "tag", "value": "@pytest.mark.usefixtures('setup')"}, {"name": "tag", "value": "api"}, {"name": "parentSuite", "value": "tests"}, {"name": "suite", "value": "test_api_resource"}, {"name": "subSuite", "value": "TestusersAPI"}, {"name": "host", "value": "Saber"}, {"name": "thread", "value": "9660-MainThread"}, {"name": "framework", "value": "pytest"}, {"name": "language", "value": "cpython3"}, {"name": "package", "value": "tests.test_api_resource"}]}