{"name": "test_update_users[NoValid- Book not found]", "status": "failed", "statusDetails": {"message": "Failed: [ERROR] Invalid id from Excel: '0.0'", "trace": "self = <tests.test_api_resource.TestusersAPI object at 0x000002D5CD1AD6A0>, data = {'action': 'update_by_id', 'expected': True, 'job': '', 'name': 'Nobody', ...}\n\n    @allure.description(\"Updates users details by users ID.\")\n    @pytest.mark.parametrize(*load_test_data(\"apis\", \"update_by_id\", parametrize=True))\n    def test_update_users(self, data):\n        expected = parse_bool(data.get(\"expected\"))\n        try:\n>           id = extract_id(data, fallback_id=self.__class__.created_ids[0])\nE           IndexError: list index out of range\n\ntests\\test_api_resource.py:45: IndexError\n\nDuring handling of the above exception, another exception occurred:\n\nself = <tests.test_api_resource.TestusersAPI object at 0x000002D5CD1AD6A0>, data = {'action': 'update_by_id', 'expected': True, 'job': '', 'name': 'Nobody', ...}\n\n    @allure.description(\"Updates users details by users ID.\")\n    @pytest.mark.parametrize(*load_test_data(\"apis\", \"update_by_id\", parametrize=True))\n    def test_update_users(self, data):\n        expected = parse_bool(data.get(\"expected\"))\n        try:\n            id = extract_id(data, fallback_id=self.__class__.created_ids[0])\n        except Exception:\n>           pytest.fail(f\"[ERROR] Invalid id from Excel: '{data.get('id')}'\")\nE           Failed: [ERROR] Invalid id from Excel: '0.0'\n\ntests\\test_api_resource.py:47: Failed"}, "description": "Updates users details by users ID.", "attachments": [{"name": "‚è∞ Test Start Time", "source": "ca7b805f-e01a-4f99-907f-b606be6b25c7-attachment.txt", "type": "text/plain"}, {"name": "üèÅ Test End Time", "source": "e9bbbaba-1b19-408f-920f-10484d988cb3-attachment.txt", "type": "text/plain"}, {"name": "‚è±Ô∏è Test Duration", "source": "6264a8e4-3166-431f-b5f0-e0f5bd9a5bc8-attachment.txt", "type": "text/plain"}, {"name": "[None] request", "source": "f7332377-054b-453f-91b3-cfff812eee67-attachment.txt", "type": "text/plain"}, {"name": "Allure Attachment Error", "source": "9b9418cb-d63b-4b7f-a108-84d4fd5f5e38-attachment.txt", "type": "text/plain"}], "parameters": [{"name": "data", "value": "{'action': 'update_by_id', 'id': 0.0, 'name': 'Nobody', 'job': '', 'expected': True, 'note': 'NoValid- Book not found'}"}], "start": 1753286092346, "stop": 1753286092347, "uuid": "aacfa343-23a9-4c5d-81e7-504ae6386312", "historyId": "0c69d8e795745ed4145a7a5bb1271633", "testCaseId": "606f5d6c173cdf14acb8881bab7fb526", "fullName": "tests.test_api_resource.TestusersAPI#test_update_users", "labels": [{"name": "epic", "value": "users API"}, {"name": "tag", "value": "@pytest.mark.usefixtures('setup')"}, {"name": "tag", "value": "api"}, {"name": "parentSuite", "value": "tests"}, {"name": "suite", "value": "test_api_resource"}, {"name": "subSuite", "value": "TestusersAPI"}, {"name": "host", "value": "Saber"}, {"name": "thread", "value": "9848-MainThread"}, {"name": "framework", "value": "pytest"}, {"name": "language", "value": "cpython3"}, {"name": "package", "value": "tests.test_api_resource"}]}