{"name": "test_update_users[Valid-Update Full Data]", "status": "failed", "statusDetails": {"message": "Failed: [ERROR] Invalid id from Excel: '1.0'", "trace": "self = <tests.test_api_resource.TestusersAPI object at 0x0000023C05BC1490>, data = {'action': 'update_by_id', 'expected': True, 'job': 'arch', 'name': 'Updated Name', ...}\n\n    @allure.description(\"Updates users details by users ID.\")\n    @pytest.mark.parametrize(*load_test_data(\"apis\", \"update_by_id\", parametrize=True))\n    def test_update_users(self, data):\n        expected = parse_bool(data.get(\"expected\"))\n        try:\n>           id = extract_id(data, fallback_id=self.__class__.created_ids[0])\nE           IndexError: list index out of range\n\ntests\\test_api_resource.py:45: IndexError\n\nDuring handling of the above exception, another exception occurred:\n\nself = <tests.test_api_resource.TestusersAPI object at 0x0000023C05BC1490>, data = {'action': 'update_by_id', 'expected': True, 'job': 'arch', 'name': 'Updated Name', ...}\n\n    @allure.description(\"Updates users details by users ID.\")\n    @pytest.mark.parametrize(*load_test_data(\"apis\", \"update_by_id\", parametrize=True))\n    def test_update_users(self, data):\n        expected = parse_bool(data.get(\"expected\"))\n        try:\n            id = extract_id(data, fallback_id=self.__class__.created_ids[0])\n        except Exception:\n>           pytest.fail(f\"[ERROR] Invalid id from Excel: '{data.get('id')}'\")\nE           Failed: [ERROR] Invalid id from Excel: '1.0'\n\ntests\\test_api_resource.py:47: Failed"}, "description": "Updates users details by users ID.", "attachments": [{"name": "‚è∞ Test Start Time", "source": "f9500300-eb9f-44d7-97be-0dbdfbf59f06-attachment.txt", "type": "text/plain"}, {"name": "üèÅ Test End Time", "source": "3320df5b-5e0c-4412-b2bb-b4e342a46df6-attachment.txt", "type": "text/plain"}, {"name": "‚è±Ô∏è Test Duration", "source": "d380189c-bf7a-433b-8b37-44a2f28ffa86-attachment.txt", "type": "text/plain"}, {"name": "[None] request", "source": "2b0bd26c-ecb4-4fc1-b6c8-e8306811b78e-attachment.txt", "type": "text/plain"}, {"name": "Allure Attachment Error", "source": "4d860f4f-d8f8-49c9-9156-212eb2d3aecb-attachment.txt", "type": "text/plain"}], "parameters": [{"name": "data", "value": "{'action': 'update_by_id', 'id': 1.0, 'name': 'Updated Name', 'job': 'arch', 'expected': True, 'note': 'Valid-Update Full Data'}"}], "start": 1753285522941, "stop": 1753285522942, "uuid": "c4bfb3cd-fb65-4aa1-add2-c8ecb5b41ad8", "historyId": "3d8c5cd125782ff1eb36301e47b55889", "testCaseId": "606f5d6c173cdf14acb8881bab7fb526", "fullName": "tests.test_api_resource.TestusersAPI#test_update_users", "labels": [{"name": "epic", "value": "users API"}, {"name": "tag", "value": "@pytest.mark.usefixtures('setup')"}, {"name": "tag", "value": "api"}, {"name": "parentSuite", "value": "tests"}, {"name": "suite", "value": "test_api_resource"}, {"name": "subSuite", "value": "TestusersAPI"}, {"name": "host", "value": "Saber"}, {"name": "thread", "value": "10540-MainThread"}, {"name": "framework", "value": "pytest"}, {"name": "language", "value": "cpython3"}, {"name": "package", "value": "tests.test_api_resource"}]}