{"name": "test_update_users[NoValid- Book not found]", "status": "failed", "statusDetails": {"message": "Failed: [ERROR] Invalid id from Excel: '0.0'", "trace": "self = <tests.test_api_resource.TestusersAPI object at 0x00000203D44E96A0>, data = {'action': 'update_by_id', 'expected': False, 'job': '', 'name': 'Nobody', ...}\n\n    @allure.description(\"Updates users details by users ID.\")\n    @pytest.mark.parametrize(*load_test_data(\"apis\", \"update_by_id\", parametrize=True))\n    def test_update_users(self, data):\n        expected = parse_bool(data.get(\"expected\"))\n        try:\n>           id = extract_id(data, fallback_id=self.__class__.created_ids[0])\nE           IndexError: list index out of range\n\ntests\\test_api_resource.py:45: IndexError\n\nDuring handling of the above exception, another exception occurred:\n\nself = <tests.test_api_resource.TestusersAPI object at 0x00000203D44E96A0>, data = {'action': 'update_by_id', 'expected': False, 'job': '', 'name': 'Nobody', ...}\n\n    @allure.description(\"Updates users details by users ID.\")\n    @pytest.mark.parametrize(*load_test_data(\"apis\", \"update_by_id\", parametrize=True))\n    def test_update_users(self, data):\n        expected = parse_bool(data.get(\"expected\"))\n        try:\n            id = extract_id(data, fallback_id=self.__class__.created_ids[0])\n        except Exception:\n>           pytest.fail(f\"[ERROR] Invalid id from Excel: '{data.get('id')}'\")\nE           Failed: [ERROR] Invalid id from Excel: '0.0'\n\ntests\\test_api_resource.py:47: Failed"}, "description": "Updates users details by users ID.", "attachments": [{"name": "‚è∞ Test Start Time", "source": "fdcc3442-bde4-4d17-8d9c-65a91e8be71e-attachment.txt", "type": "text/plain"}, {"name": "üèÅ Test End Time", "source": "3307adbf-d5b4-4408-a8a3-14b39d29470c-attachment.txt", "type": "text/plain"}, {"name": "‚è±Ô∏è Test Duration", "source": "6e4e367b-4285-4a23-9458-5ec92121b38f-attachment.txt", "type": "text/plain"}, {"name": "[None] request", "source": "c033aa68-0104-43b6-babe-e062be7c036c-attachment.txt", "type": "text/plain"}, {"name": "Allure Attachment Error", "source": "de12788a-0758-4a79-bb2a-d3c06f754dec-attachment.txt", "type": "text/plain"}], "parameters": [{"name": "data", "value": "{'action': 'update_by_id', 'id': 0.0, 'name': 'Nobody', 'job': '', 'expected': False, 'note': 'NoValid- Book not found'}"}], "start": 1753285695678, "stop": 1753285695679, "uuid": "bd57b204-5b3e-4729-8c98-becf9445de87", "historyId": "3fa25077474b9b27ae8c4b68430a7af2", "testCaseId": "606f5d6c173cdf14acb8881bab7fb526", "fullName": "tests.test_api_resource.TestusersAPI#test_update_users", "labels": [{"name": "epic", "value": "users API"}, {"name": "tag", "value": "@pytest.mark.usefixtures('setup')"}, {"name": "tag", "value": "api"}, {"name": "parentSuite", "value": "tests"}, {"name": "suite", "value": "test_api_resource"}, {"name": "subSuite", "value": "TestusersAPI"}, {"name": "host", "value": "Saber"}, {"name": "thread", "value": "9804-MainThread"}, {"name": "framework", "value": "pytest"}, {"name": "language", "value": "cpython3"}, {"name": "package", "value": "tests.test_api_resource"}]}