{"name": "test_update_users[NO-Valid-Partial Update]", "status": "failed", "statusDetails": {"message": "Failed: [ERROR] Invalid id from Excel: '999999999.0'", "trace": "self = <tests.test_api_resource.TestusersAPI object at 0x00000211267418C0>, data = {'action': 'update_by_id', 'expected': True, 'job': '', 'name': 'Only Author', ...}\n\n    @allure.description(\"Updates users details by users ID.\")\n    @pytest.mark.parametrize(*load_test_data(\"apis\", \"update_by_id\", parametrize=True))\n    def test_update_users(self, data):\n        expected = parse_bool(data.get(\"expected\"))\n        try:\n>           id = extract_id(data, fallback_id=self.__class__.created_ids[0])\nE           IndexError: list index out of range\n\ntests\\test_api_resource.py:45: IndexError\n\nDuring handling of the above exception, another exception occurred:\n\nself = <tests.test_api_resource.TestusersAPI object at 0x00000211267418C0>, data = {'action': 'update_by_id', 'expected': True, 'job': '', 'name': 'Only Author', ...}\n\n    @allure.description(\"Updates users details by users ID.\")\n    @pytest.mark.parametrize(*load_test_data(\"apis\", \"update_by_id\", parametrize=True))\n    def test_update_users(self, data):\n        expected = parse_bool(data.get(\"expected\"))\n        try:\n            id = extract_id(data, fallback_id=self.__class__.created_ids[0])\n        except Exception:\n>           pytest.fail(f\"[ERROR] Invalid id from Excel: '{data.get('id')}'\")\nE           Failed: [ERROR] Invalid id from Excel: '999999999.0'\n\ntests\\test_api_resource.py:47: Failed"}, "description": "Updates users details by users ID.", "attachments": [{"name": "‚è∞ Test Start Time", "source": "a3cc4de8-28cf-47bf-a912-13e05f4657a0-attachment.txt", "type": "text/plain"}, {"name": "üèÅ Test End Time", "source": "fa394327-d034-420c-8ebd-41f70470d82c-attachment.txt", "type": "text/plain"}, {"name": "‚è±Ô∏è Test Duration", "source": "1b6f0272-016f-45a4-8760-b16d3196422b-attachment.txt", "type": "text/plain"}, {"name": "[None] request", "source": "2c9c09ef-810f-427d-96c8-b40bb4021035-attachment.txt", "type": "text/plain"}, {"name": "Allure Attachment Error", "source": "6500e076-f9e2-4c99-ab89-f150b2a77a39-attachment.txt", "type": "text/plain"}], "parameters": [{"name": "data", "value": "{'action': 'update_by_id', 'id': 999999999.0, 'name': 'Only Author', 'job': '', 'expected': True, 'note': 'NO-Valid-Partial Update'}"}], "start": 1753287877697, "stop": 1753287877699, "uuid": "97d27559-6143-48ba-a411-71f69fa6a7d8", "historyId": "442892ba62cdedb55a1a955a0064286c", "testCaseId": "606f5d6c173cdf14acb8881bab7fb526", "fullName": "tests.test_api_resource.TestusersAPI#test_update_users", "labels": [{"name": "epic", "value": "users API"}, {"name": "tag", "value": "@pytest.mark.usefixtures('setup')"}, {"name": "tag", "value": "api"}, {"name": "parentSuite", "value": "tests"}, {"name": "suite", "value": "test_api_resource"}, {"name": "subSuite", "value": "TestusersAPI"}, {"name": "host", "value": "Saber"}, {"name": "thread", "value": "16924-MainThread"}, {"name": "framework", "value": "pytest"}, {"name": "language", "value": "cpython3"}, {"name": "package", "value": "tests.test_api_resource"}]}