{"name": "test_update_users[Valid-Update Full Data]", "status": "failed", "statusDetails": {"message": "Failed: [ERROR] Invalid id from Excel: '1.0'", "trace": "self = <tests.test_api_resource.TestusersAPI object at 0x0000021126798290>, data = {'action': 'update_by_id', 'expected': True, 'job': 'arch', 'name': 'Updated Name', ...}\n\n    @allure.description(\"Updates users details by users ID.\")\n    @pytest.mark.parametrize(*load_test_data(\"apis\", \"update_by_id\", parametrize=True))\n    def test_update_users(self, data):\n        expected = parse_bool(data.get(\"expected\"))\n        try:\n>           id = extract_id(data, fallback_id=self.__class__.created_ids[0])\nE           IndexError: list index out of range\n\ntests\\test_api_resource.py:45: IndexError\n\nDuring handling of the above exception, another exception occurred:\n\nself = <tests.test_api_resource.TestusersAPI object at 0x0000021126798290>, data = {'action': 'update_by_id', 'expected': True, 'job': 'arch', 'name': 'Updated Name', ...}\n\n    @allure.description(\"Updates users details by users ID.\")\n    @pytest.mark.parametrize(*load_test_data(\"apis\", \"update_by_id\", parametrize=True))\n    def test_update_users(self, data):\n        expected = parse_bool(data.get(\"expected\"))\n        try:\n            id = extract_id(data, fallback_id=self.__class__.created_ids[0])\n        except Exception:\n>           pytest.fail(f\"[ERROR] Invalid id from Excel: '{data.get('id')}'\")\nE           Failed: [ERROR] Invalid id from Excel: '1.0'\n\ntests\\test_api_resource.py:47: Failed"}, "description": "Updates users details by users ID.", "attachments": [{"name": "‚è∞ Test Start Time", "source": "27155024-79e3-4961-83fb-1e85621b9a60-attachment.txt", "type": "text/plain"}, {"name": "üèÅ Test End Time", "source": "ad4c9c73-49b6-45a9-92b6-9ad9b242cefa-attachment.txt", "type": "text/plain"}, {"name": "‚è±Ô∏è Test Duration", "source": "258eeda8-f1f7-40a3-9a04-07789579feea-attachment.txt", "type": "text/plain"}, {"name": "[None] request", "source": "bb21a9d0-2271-4456-abcc-b18eeb0dd1f4-attachment.txt", "type": "text/plain"}, {"name": "Allure Attachment Error", "source": "31be0c4e-2340-4c89-bef0-dd862a43936f-attachment.txt", "type": "text/plain"}], "parameters": [{"name": "data", "value": "{'action': 'update_by_id', 'id': 1.0, 'name': 'Updated Name', 'job': 'arch', 'expected': True, 'note': 'Valid-Update Full Data'}"}], "start": 1753287877688, "stop": 1753287877689, "uuid": "d8ebcac5-66d4-46d9-a037-9777f013e0db", "historyId": "3d8c5cd125782ff1eb36301e47b55889", "testCaseId": "606f5d6c173cdf14acb8881bab7fb526", "fullName": "tests.test_api_resource.TestusersAPI#test_update_users", "labels": [{"name": "epic", "value": "users API"}, {"name": "tag", "value": "@pytest.mark.usefixtures('setup')"}, {"name": "tag", "value": "api"}, {"name": "parentSuite", "value": "tests"}, {"name": "suite", "value": "test_api_resource"}, {"name": "subSuite", "value": "TestusersAPI"}, {"name": "host", "value": "Saber"}, {"name": "thread", "value": "16924-MainThread"}, {"name": "framework", "value": "pytest"}, {"name": "language", "value": "cpython3"}, {"name": "package", "value": "tests.test_api_resource"}]}