{"name": "test_update_users[NO-Valid-Partial Update]", "status": "failed", "statusDetails": {"message": "Failed: [ERROR] Invalid id from Excel: '999999999.0'", "trace": "self = <tests.test_api_resource.TestusersAPI object at 0x00000203D44E98C0>, data = {'action': 'update_by_id', 'expected': False, 'job': '', 'name': 'Only Author', ...}\n\n    @allure.description(\"Updates users details by users ID.\")\n    @pytest.mark.parametrize(*load_test_data(\"apis\", \"update_by_id\", parametrize=True))\n    def test_update_users(self, data):\n        expected = parse_bool(data.get(\"expected\"))\n        try:\n>           id = extract_id(data, fallback_id=self.__class__.created_ids[0])\nE           IndexError: list index out of range\n\ntests\\test_api_resource.py:45: IndexError\n\nDuring handling of the above exception, another exception occurred:\n\nself = <tests.test_api_resource.TestusersAPI object at 0x00000203D44E98C0>, data = {'action': 'update_by_id', 'expected': False, 'job': '', 'name': 'Only Author', ...}\n\n    @allure.description(\"Updates users details by users ID.\")\n    @pytest.mark.parametrize(*load_test_data(\"apis\", \"update_by_id\", parametrize=True))\n    def test_update_users(self, data):\n        expected = parse_bool(data.get(\"expected\"))\n        try:\n            id = extract_id(data, fallback_id=self.__class__.created_ids[0])\n        except Exception:\n>           pytest.fail(f\"[ERROR] Invalid id from Excel: '{data.get('id')}'\")\nE           Failed: [ERROR] Invalid id from Excel: '999999999.0'\n\ntests\\test_api_resource.py:47: Failed"}, "description": "Updates users details by users ID.", "attachments": [{"name": "‚è∞ Test Start Time", "source": "20c59bde-bc72-4d49-bba6-b18ea90a0e24-attachment.txt", "type": "text/plain"}, {"name": "üèÅ Test End Time", "source": "ef48221d-f2b0-4566-918a-cec025ba8055-attachment.txt", "type": "text/plain"}, {"name": "‚è±Ô∏è Test Duration", "source": "8606d4f3-45aa-4832-a87a-5f805425356b-attachment.txt", "type": "text/plain"}, {"name": "[None] request", "source": "49433d69-432b-40d8-bf92-3dd34cadee52-attachment.txt", "type": "text/plain"}, {"name": "Allure Attachment Error", "source": "23b07789-201e-4bc1-b091-25db6cceec56-attachment.txt", "type": "text/plain"}], "parameters": [{"name": "data", "value": "{'action': 'update_by_id', 'id': 999999999.0, 'name': 'Only Author', 'job': '', 'expected': False, 'note': 'NO-Valid-Partial Update'}"}], "start": 1753285695671, "stop": 1753285695672, "uuid": "5af70add-4baf-420b-b6a0-b8a93ab24096", "historyId": "4705b3c1fb472b0a88e28c9a2b994b2b", "testCaseId": "606f5d6c173cdf14acb8881bab7fb526", "fullName": "tests.test_api_resource.TestusersAPI#test_update_users", "labels": [{"name": "epic", "value": "users API"}, {"name": "tag", "value": "@pytest.mark.usefixtures('setup')"}, {"name": "tag", "value": "api"}, {"name": "parentSuite", "value": "tests"}, {"name": "suite", "value": "test_api_resource"}, {"name": "subSuite", "value": "TestusersAPI"}, {"name": "host", "value": "Saber"}, {"name": "thread", "value": "9804-MainThread"}, {"name": "framework", "value": "pytest"}, {"name": "language", "value": "cpython3"}, {"name": "package", "value": "tests.test_api_resource"}]}