{"name": "test_update_users[NoValid- Book not found]", "status": "failed", "statusDetails": {"message": "Failed: [ERROR] Invalid id from Excel: '0.0'", "trace": "self = <tests.test_api_resource.TestusersAPI object at 0x00000264C84B96A0>, data = {'action': 'update_by_id', 'expected': True, 'job': '', 'name': 'Nobody', ...}\n\n    @allure.description(\"Updates users details by users ID.\")\n    @pytest.mark.parametrize(*load_test_data(\"apis\", \"update_by_id\", parametrize=True))\n    def test_update_users(self, data):\n        expected = parse_bool(data.get(\"expected\"))\n        try:\n>           id = extract_id(data, fallback_id=self.__class__.created_ids[0])\nE           IndexError: list index out of range\n\ntests\\test_api_resource.py:45: IndexError\n\nDuring handling of the above exception, another exception occurred:\n\nself = <tests.test_api_resource.TestusersAPI object at 0x00000264C84B96A0>, data = {'action': 'update_by_id', 'expected': True, 'job': '', 'name': 'Nobody', ...}\n\n    @allure.description(\"Updates users details by users ID.\")\n    @pytest.mark.parametrize(*load_test_data(\"apis\", \"update_by_id\", parametrize=True))\n    def test_update_users(self, data):\n        expected = parse_bool(data.get(\"expected\"))\n        try:\n            id = extract_id(data, fallback_id=self.__class__.created_ids[0])\n        except Exception:\n>           pytest.fail(f\"[ERROR] Invalid id from Excel: '{data.get('id')}'\")\nE           Failed: [ERROR] Invalid id from Excel: '0.0'\n\ntests\\test_api_resource.py:47: Failed"}, "description": "Updates users details by users ID.", "attachments": [{"name": "‚è∞ Test Start Time", "source": "70690196-7185-4426-ba07-3448098477f3-attachment.txt", "type": "text/plain"}, {"name": "üèÅ Test End Time", "source": "adcce0e0-3967-4307-8ebf-0420e0d42c18-attachment.txt", "type": "text/plain"}, {"name": "‚è±Ô∏è Test Duration", "source": "9f27dc95-cb43-48dc-b6ab-6b66f784fe39-attachment.txt", "type": "text/plain"}, {"name": "[None] request", "source": "70d9a114-aa83-4225-b7cd-b1fa7cf0bb40-attachment.txt", "type": "text/plain"}, {"name": "Allure Attachment Error", "source": "ef0c2a2d-f99c-492c-a158-fc196d99aee5-attachment.txt", "type": "text/plain"}], "parameters": [{"name": "data", "value": "{'action': 'update_by_id', 'id': 0.0, 'name': 'Nobody', 'job': '', 'expected': True, 'note': 'NoValid- Book not found'}"}], "start": 1753288008213, "stop": 1753288008214, "uuid": "88d747a1-cbd6-43f3-b70a-d3d6f24155ae", "historyId": "0c69d8e795745ed4145a7a5bb1271633", "testCaseId": "606f5d6c173cdf14acb8881bab7fb526", "fullName": "tests.test_api_resource.TestusersAPI#test_update_users", "labels": [{"name": "epic", "value": "users API"}, {"name": "tag", "value": "@pytest.mark.usefixtures('setup')"}, {"name": "tag", "value": "api"}, {"name": "parentSuite", "value": "tests"}, {"name": "suite", "value": "test_api_resource"}, {"name": "subSuite", "value": "TestusersAPI"}, {"name": "host", "value": "Saber"}, {"name": "thread", "value": "5476-MainThread"}, {"name": "framework", "value": "pytest"}, {"name": "language", "value": "cpython3"}, {"name": "package", "value": "tests.test_api_resource"}]}