{"name": "test_update_users[NO-Valid-Partial Update]", "status": "failed", "statusDetails": {"message": "Failed: [ERROR] Invalid id from Excel: '999999999.0'", "trace": "self = <tests.test_api_resource.TestusersAPI object at 0x000002D5CD1AD8C0>, data = {'action': 'update_by_id', 'expected': True, 'job': '', 'name': 'Only Author', ...}\n\n    @allure.description(\"Updates users details by users ID.\")\n    @pytest.mark.parametrize(*load_test_data(\"apis\", \"update_by_id\", parametrize=True))\n    def test_update_users(self, data):\n        expected = parse_bool(data.get(\"expected\"))\n        try:\n>           id = extract_id(data, fallback_id=self.__class__.created_ids[0])\nE           IndexError: list index out of range\n\ntests\\test_api_resource.py:45: IndexError\n\nDuring handling of the above exception, another exception occurred:\n\nself = <tests.test_api_resource.TestusersAPI object at 0x000002D5CD1AD8C0>, data = {'action': 'update_by_id', 'expected': True, 'job': '', 'name': 'Only Author', ...}\n\n    @allure.description(\"Updates users details by users ID.\")\n    @pytest.mark.parametrize(*load_test_data(\"apis\", \"update_by_id\", parametrize=True))\n    def test_update_users(self, data):\n        expected = parse_bool(data.get(\"expected\"))\n        try:\n            id = extract_id(data, fallback_id=self.__class__.created_ids[0])\n        except Exception:\n>           pytest.fail(f\"[ERROR] Invalid id from Excel: '{data.get('id')}'\")\nE           Failed: [ERROR] Invalid id from Excel: '999999999.0'\n\ntests\\test_api_resource.py:47: Failed"}, "description": "Updates users details by users ID.", "attachments": [{"name": "‚è∞ Test Start Time", "source": "b47af75d-14bd-4dd1-9d66-802a09cee096-attachment.txt", "type": "text/plain"}, {"name": "üèÅ Test End Time", "source": "30b3875d-012e-493a-b0c1-75b4695ca1b5-attachment.txt", "type": "text/plain"}, {"name": "‚è±Ô∏è Test Duration", "source": "ba4aeef7-3efb-44fc-a0b9-0227ec1a5c80-attachment.txt", "type": "text/plain"}, {"name": "[None] request", "source": "dd3601d0-adb0-4df7-997d-5c6a9540a377-attachment.txt", "type": "text/plain"}, {"name": "Allure Attachment Error", "source": "f2a906ae-6f65-4b2b-8ae3-da22b8159784-attachment.txt", "type": "text/plain"}], "parameters": [{"name": "data", "value": "{'action': 'update_by_id', 'id': 999999999.0, 'name': 'Only Author', 'job': '', 'expected': True, 'note': 'NO-Valid-Partial Update'}"}], "start": 1753286092337, "stop": 1753286092339, "uuid": "ac3d132b-5bc2-445f-843f-0f671fca7dfc", "historyId": "442892ba62cdedb55a1a955a0064286c", "testCaseId": "606f5d6c173cdf14acb8881bab7fb526", "fullName": "tests.test_api_resource.TestusersAPI#test_update_users", "labels": [{"name": "epic", "value": "users API"}, {"name": "tag", "value": "@pytest.mark.usefixtures('setup')"}, {"name": "tag", "value": "api"}, {"name": "parentSuite", "value": "tests"}, {"name": "suite", "value": "test_api_resource"}, {"name": "subSuite", "value": "TestusersAPI"}, {"name": "host", "value": "Saber"}, {"name": "thread", "value": "9848-MainThread"}, {"name": "framework", "value": "pytest"}, {"name": "language", "value": "cpython3"}, {"name": "package", "value": "tests.test_api_resource"}]}