{"name": "test_update_users[Valid-Update Full Data]", "status": "failed", "statusDetails": {"message": "Failed: [ERROR] Invalid id from Excel: '1.0'", "trace": "self = <tests.test_api_resource.TestusersAPI object at 0x000002D5CD208050>, data = {'action': 'update_by_id', 'expected': True, 'job': 'arch', 'name': 'Updated Name', ...}\n\n    @allure.description(\"Updates users details by users ID.\")\n    @pytest.mark.parametrize(*load_test_data(\"apis\", \"update_by_id\", parametrize=True))\n    def test_update_users(self, data):\n        expected = parse_bool(data.get(\"expected\"))\n        try:\n>           id = extract_id(data, fallback_id=self.__class__.created_ids[0])\nE           IndexError: list index out of range\n\ntests\\test_api_resource.py:45: IndexError\n\nDuring handling of the above exception, another exception occurred:\n\nself = <tests.test_api_resource.TestusersAPI object at 0x000002D5CD208050>, data = {'action': 'update_by_id', 'expected': True, 'job': 'arch', 'name': 'Updated Name', ...}\n\n    @allure.description(\"Updates users details by users ID.\")\n    @pytest.mark.parametrize(*load_test_data(\"apis\", \"update_by_id\", parametrize=True))\n    def test_update_users(self, data):\n        expected = parse_bool(data.get(\"expected\"))\n        try:\n            id = extract_id(data, fallback_id=self.__class__.created_ids[0])\n        except Exception:\n>           pytest.fail(f\"[ERROR] Invalid id from Excel: '{data.get('id')}'\")\nE           Failed: [ERROR] Invalid id from Excel: '1.0'\n\ntests\\test_api_resource.py:47: Failed"}, "description": "Updates users details by users ID.", "attachments": [{"name": "‚è∞ Test Start Time", "source": "2acb1f55-ad48-4475-beb6-b928161af8ff-attachment.txt", "type": "text/plain"}, {"name": "üèÅ Test End Time", "source": "1d824e5d-0d63-4631-90d0-35349754f94e-attachment.txt", "type": "text/plain"}, {"name": "‚è±Ô∏è Test Duration", "source": "6bbfc554-2741-4a3f-9d6d-fd293b4d5c28-attachment.txt", "type": "text/plain"}, {"name": "[None] request", "source": "3a88fc30-4a1f-468b-a9a0-d0c76ea1aadc-attachment.txt", "type": "text/plain"}, {"name": "Allure Attachment Error", "source": "80b158fa-b506-4453-875d-c0cd99015e4b-attachment.txt", "type": "text/plain"}], "parameters": [{"name": "data", "value": "{'action': 'update_by_id', 'id': 1.0, 'name': 'Updated Name', 'job': 'arch', 'expected': True, 'note': 'Valid-Update Full Data'}"}], "start": 1753286092329, "stop": 1753286092330, "uuid": "08d0ebaa-0a88-4319-a1fe-756c137134cf", "historyId": "3d8c5cd125782ff1eb36301e47b55889", "testCaseId": "606f5d6c173cdf14acb8881bab7fb526", "fullName": "tests.test_api_resource.TestusersAPI#test_update_users", "labels": [{"name": "epic", "value": "users API"}, {"name": "tag", "value": "@pytest.mark.usefixtures('setup')"}, {"name": "tag", "value": "api"}, {"name": "parentSuite", "value": "tests"}, {"name": "suite", "value": "test_api_resource"}, {"name": "subSuite", "value": "TestusersAPI"}, {"name": "host", "value": "Saber"}, {"name": "thread", "value": "9848-MainThread"}, {"name": "framework", "value": "pytest"}, {"name": "language", "value": "cpython3"}, {"name": "package", "value": "tests.test_api_resource"}]}